2020-04-10 15:20:54,963 - f:\GitRepo\auto_interface_test\basic\RunTestcase.py[line:202] - ERROR: 出现异常Traceback (most recent call last):
  File "f:\GitRepo\auto_interface_test\basic\Testcase.py", line 48, in writeTestResult
    self.operateExcel.writeCellCurrentTime(sheetObj,rowNo=rowNo,colsNo=colsDict[colsNo][0])
  File "f:\GitRepo\auto_interface_test\util\OperateExcel.py", line 153, in writeCellCurrentTime
    raise e
  File "f:\GitRepo\auto_interface_test\util\OperateExcel.py", line 151, in writeCellCurrentTime
    self.workbook.save(self.excelFile)
  File "E:\Python37\Lib\site-packages\openpyxl\workbook\workbook.py", line 408, in save
    save_workbook(self, filename)
  File "E:\Python37\Lib\site-packages\openpyxl\writer\excel.py", line 291, in save_workbook
    archive = ZipFile(filename, 'w', ZIP_DEFLATED, allowZip64=True)
  File "E:\Python37\lib\zipfile.py", line 1204, in __init__
    self.fp = io.open(file, filemode)
PermissionError: [Errno 13] Permission denied: 'f:\\GitRepo\\auto_interface_test\\testcase\\Testcases.xlsx'

During handling of the above exception, another exception occurred:

Traceback (most recent call last):
  File "f:\GitRepo\auto_interface_test\basic\RunTestcase.py", line 187, in runTestcase
    self.testcases.writeTestResult(apiSheet, rowNo=index, colsNo="api", testResult=("pass",res.text))
  File "f:\GitRepo\auto_interface_test\basic\Testcase.py", line 55, in writeTestResult
    print(u"写excel时发生异常,",+traceback.print_exc())
TypeError: bad operand type for unary +: 'NoneType'

2020-04-10 15:20:57,130 - f:\GitRepo\auto_interface_test\basic\RunTestcase.py[line:202] - ERROR: 出现异常Traceback (most recent call last):
  File "f:\GitRepo\auto_interface_test\basic\Testcase.py", line 48, in writeTestResult
    self.operateExcel.writeCellCurrentTime(sheetObj,rowNo=rowNo,colsNo=colsDict[colsNo][0])
  File "f:\GitRepo\auto_interface_test\util\OperateExcel.py", line 153, in writeCellCurrentTime
    raise e
  File "f:\GitRepo\auto_interface_test\util\OperateExcel.py", line 151, in writeCellCurrentTime
    self.workbook.save(self.excelFile)
  File "E:\Python37\Lib\site-packages\openpyxl\workbook\workbook.py", line 408, in save
    save_workbook(self, filename)
  File "E:\Python37\Lib\site-packages\openpyxl\writer\excel.py", line 291, in save_workbook
    archive = ZipFile(filename, 'w', ZIP_DEFLATED, allowZip64=True)
  File "E:\Python37\lib\zipfile.py", line 1204, in __init__
    self.fp = io.open(file, filemode)
PermissionError: [Errno 13] Permission denied: 'f:\\GitRepo\\auto_interface_test\\testcase\\Testcases.xlsx'

During handling of the above exception, another exception occurred:

Traceback (most recent call last):
  File "f:\GitRepo\auto_interface_test\basic\RunTestcase.py", line 187, in runTestcase
    self.testcases.writeTestResult(apiSheet, rowNo=index, colsNo="api", testResult=("pass",res.text))
  File "f:\GitRepo\auto_interface_test\basic\Testcase.py", line 55, in writeTestResult
    print(u"写excel时发生异常,",+traceback.print_exc())
TypeError: bad operand type for unary +: 'NoneType'

