2020-04-07 11:27:32,622 - f:\GitRepo\auto_interface_test\basic\RunTestcase.py[line:109] - ERROR: 出现异常Traceback (most recent call last):
  File "f:\GitRepo\auto_interface_test\basic\RunTestcase.py", line 28, in runTestcase
    isExecuteColumn = self.testcases.getExecuteColumn()
  File "f:\GitRepo\auto_interface_test\basic\Testcase.py", line 19, in getExecuteColumn
    return self.operateExcel.getColumn(caseSheet,testCase_isExecute)
NameError: name 'caseSheet' is not defined

2020-04-07 11:27:45,190 - f:\GitRepo\auto_interface_test\basic\RunTestcase.py[line:109] - ERROR: 出现异常Traceback (most recent call last):
  File "f:\GitRepo\auto_interface_test\basic\RunTestcase.py", line 28, in runTestcase
    isExecuteColumn = self.testcases.getExecuteColumn()
  File "f:\GitRepo\auto_interface_test\basic\Testcase.py", line 19, in getExecuteColumn
    return self.operateExcel.getColumn(caseSheet,testCase_isExecute)
NameError: name 'caseSheet' is not defined

2020-04-07 11:30:58,980 - f:\GitRepo\auto_interface_test\basic\RunTestcase.py[line:109] - ERROR: 出现异常Traceback (most recent call last):
  File "f:\GitRepo\auto_interface_test\basic\Testcase.py", line 41, in writeTestResult
    self.operateExcel.writeCellCurrentTime(sheetObj,rowNo=rowNo,colsNo=colsDict[colsNo][0])
  File "f:\GitRepo\auto_interface_test\util\OperateExcel.py", line 147, in writeCellCurrentTime
    raise e
  File "f:\GitRepo\auto_interface_test\util\OperateExcel.py", line 145, in writeCellCurrentTime
    self.workbook.save(self.excelFile)
  File "E:\Python37\Lib\site-packages\openpyxl\workbook\workbook.py", line 408, in save
    save_workbook(self, filename)
  File "E:\Python37\Lib\site-packages\openpyxl\writer\excel.py", line 291, in save_workbook
    archive = ZipFile(filename, 'w', ZIP_DEFLATED, allowZip64=True)
  File "E:\Python37\lib\zipfile.py", line 1204, in __init__
    self.fp = io.open(file, filemode)
PermissionError: [Errno 13] Permission denied: 'f:\\GitRepo\\auto_interface_test\\testcase\\Testcases.xlsx'

During handling of the above exception, another exception occurred:

Traceback (most recent call last):
  File "f:\GitRepo\auto_interface_test\basic\RunTestcase.py", line 103, in runTestcase
    self.testcases.writeTestResult(apiSheet, rowNo=index, colsNo="api", testResult="none")
  File "f:\GitRepo\auto_interface_test\basic\Testcase.py", line 46, in writeTestResult
    print(u"写excel时发生异常,",+traceback.print_exc())
TypeError: bad operand type for unary +: 'NoneType'

2020-04-07 14:20:15,862 - f:\GitRepo\auto_interface_test\basic\RunTestcase.py[line:110] - ERROR: 出现异常Traceback (most recent call last):
  File "f:\GitRepo\auto_interface_test\basic\RunTestcase.py", line 93, in runTestcase
    if (checkData in res.text):
AttributeError: 'dict' object has no attribute 'text'

2020-04-07 14:48:43,439 - f:\GitRepo\auto_interface_test\basic\RunTestcase.py[line:121] - ERROR: 出现异常Traceback (most recent call last):
  File "f:\GitRepo\auto_interface_test\basic\RunTestcase.py", line 104, in runTestcase
    if (checkData in res.text):
TypeError: 'in <string>' requires string as left operand, not NoneType

2020-04-07 14:50:08,731 - f:\GitRepo\auto_interface_test\basic\RunTestcase.py[line:121] - ERROR: 出现异常Traceback (most recent call last):
  File "f:\GitRepo\auto_interface_test\basic\RunTestcase.py", line 104, in runTestcase
    if (checkData in res.text):
TypeError: 'in <string>' requires string as left operand, not NoneType

2020-04-07 14:51:28,931 - f:\GitRepo\auto_interface_test\basic\RunTestcase.py[line:121] - ERROR: 出现异常Traceback (most recent call last):
  File "f:\GitRepo\auto_interface_test\basic\Testcase.py", line 41, in writeTestResult
    self.operateExcel.writeCellCurrentTime(sheetObj,rowNo=rowNo,colsNo=colsDict[colsNo][0])
  File "f:\GitRepo\auto_interface_test\util\OperateExcel.py", line 147, in writeCellCurrentTime
    raise e
  File "f:\GitRepo\auto_interface_test\util\OperateExcel.py", line 145, in writeCellCurrentTime
    self.workbook.save(self.excelFile)
  File "E:\Python37\Lib\site-packages\openpyxl\workbook\workbook.py", line 408, in save
    save_workbook(self, filename)
  File "E:\Python37\Lib\site-packages\openpyxl\writer\excel.py", line 291, in save_workbook
    archive = ZipFile(filename, 'w', ZIP_DEFLATED, allowZip64=True)
  File "E:\Python37\lib\zipfile.py", line 1204, in __init__
    self.fp = io.open(file, filemode)
PermissionError: [Errno 13] Permission denied: 'f:\\GitRepo\\auto_interface_test\\testcase\\Testcases.xlsx'

During handling of the above exception, another exception occurred:

Traceback (most recent call last):
  File "f:\GitRepo\auto_interface_test\basic\RunTestcase.py", line 112, in runTestcase
    self.testcases.writeTestResult(apiSheet, rowNo=index, colsNo="api", testResult="failed")
  File "f:\GitRepo\auto_interface_test\basic\Testcase.py", line 46, in writeTestResult
    print(u"写excel时发生异常,",+traceback.print_exc())
TypeError: bad operand type for unary +: 'NoneType'

2020-04-07 15:06:08,369 - f:\GitRepo\auto_interface_test\basic\RunTestcase.py[line:121] - ERROR: 出现异常Traceback (most recent call last):
  File "f:\GitRepo\auto_interface_test\basic\Testcase.py", line 44, in writeTestResult
    rowNo=rowNo, colsNo=colsDict[colsNo][1], style=colorDict[testResult[0]])
KeyError: 'p'

During handling of the above exception, another exception occurred:

Traceback (most recent call last):
  File "f:\GitRepo\auto_interface_test\basic\RunTestcase.py", line 98, in runTestcase
    self.testcases.writeTestResult(apiSheet, rowNo=index, colsNo="api", testResult="pass")
  File "f:\GitRepo\auto_interface_test\basic\Testcase.py", line 48, in writeTestResult
    print(u"写excel时发生异常,",+traceback.print_exc())
TypeError: bad operand type for unary +: 'NoneType'

2020-04-07 15:25:50,764 - f:\GitRepo\auto_interface_test\basic\RunTestcase.py[line:201] - ERROR: 出现异常Traceback (most recent call last):
  File "f:\GitRepo\auto_interface_test\basic\Testcase.py", line 41, in writeTestResult
    self.operateExcel.writeCellCurrentTime(sheetObj,rowNo=rowNo,colsNo=colsDict[colsNo][0])
  File "f:\GitRepo\auto_interface_test\util\OperateExcel.py", line 147, in writeCellCurrentTime
    raise e
  File "f:\GitRepo\auto_interface_test\util\OperateExcel.py", line 145, in writeCellCurrentTime
    self.workbook.save(self.excelFile)
  File "E:\Python37\Lib\site-packages\openpyxl\workbook\workbook.py", line 408, in save
    save_workbook(self, filename)
  File "E:\Python37\Lib\site-packages\openpyxl\writer\excel.py", line 291, in save_workbook
    archive = ZipFile(filename, 'w', ZIP_DEFLATED, allowZip64=True)
  File "E:\Python37\lib\zipfile.py", line 1204, in __init__
    self.fp = io.open(file, filemode)
PermissionError: [Errno 13] Permission denied: 'f:\\GitRepo\\auto_interface_test\\testcase\\Testcases.xlsx'

During handling of the above exception, another exception occurred:

Traceback (most recent call last):
  File "f:\GitRepo\auto_interface_test\basic\RunTestcase.py", line 192, in runTestcase
    self.testcases.writeTestResult(apiSheet, rowNo=index, colsNo="api", testResult=("failed",res.text))
  File "f:\GitRepo\auto_interface_test\basic\Testcase.py", line 48, in writeTestResult
    print(u"写excel时发生异常,",+traceback.print_exc())
TypeError: bad operand type for unary +: 'NoneType'

2020-04-07 15:27:42,477 - f:\GitRepo\auto_interface_test\basic\RunTestcase.py[line:201] - ERROR: 出现异常Traceback (most recent call last):
  File "f:\GitRepo\auto_interface_test\basic\Testcase.py", line 41, in writeTestResult
    self.operateExcel.writeCellCurrentTime(sheetObj,rowNo=rowNo,colsNo=colsDict[colsNo][0])
  File "f:\GitRepo\auto_interface_test\util\OperateExcel.py", line 147, in writeCellCurrentTime
    raise e
  File "f:\GitRepo\auto_interface_test\util\OperateExcel.py", line 145, in writeCellCurrentTime
    self.workbook.save(self.excelFile)
  File "E:\Python37\Lib\site-packages\openpyxl\workbook\workbook.py", line 408, in save
    save_workbook(self, filename)
  File "E:\Python37\Lib\site-packages\openpyxl\writer\excel.py", line 291, in save_workbook
    archive = ZipFile(filename, 'w', ZIP_DEFLATED, allowZip64=True)
  File "E:\Python37\lib\zipfile.py", line 1204, in __init__
    self.fp = io.open(file, filemode)
PermissionError: [Errno 13] Permission denied: 'f:\\GitRepo\\auto_interface_test\\testcase\\Testcases.xlsx'

During handling of the above exception, another exception occurred:

Traceback (most recent call last):
  File "f:\GitRepo\auto_interface_test\basic\RunTestcase.py", line 192, in runTestcase
    self.testcases.writeTestResult(apiSheet, rowNo=index, colsNo="api", testResult=("failed",res.text))
  File "f:\GitRepo\auto_interface_test\basic\Testcase.py", line 48, in writeTestResult
    print(u"写excel时发生异常,",+traceback.print_exc())
TypeError: bad operand type for unary +: 'NoneType'

2020-04-07 15:30:10,487 - f:\GitRepo\auto_interface_test\basic\RunTestcase.py[line:201] - ERROR: 出现异常Traceback (most recent call last):
  File "f:\GitRepo\auto_interface_test\basic\Testcase.py", line 41, in writeTestResult
    self.operateExcel.writeCellCurrentTime(sheetObj,rowNo=rowNo,colsNo=colsDict[colsNo][0])
  File "f:\GitRepo\auto_interface_test\util\OperateExcel.py", line 147, in writeCellCurrentTime
    raise e
  File "f:\GitRepo\auto_interface_test\util\OperateExcel.py", line 145, in writeCellCurrentTime
    self.workbook.save(self.excelFile)
  File "E:\Python37\Lib\site-packages\openpyxl\workbook\workbook.py", line 408, in save
    save_workbook(self, filename)
  File "E:\Python37\Lib\site-packages\openpyxl\writer\excel.py", line 291, in save_workbook
    archive = ZipFile(filename, 'w', ZIP_DEFLATED, allowZip64=True)
  File "E:\Python37\lib\zipfile.py", line 1204, in __init__
    self.fp = io.open(file, filemode)
PermissionError: [Errno 13] Permission denied: 'f:\\GitRepo\\auto_interface_test\\testcase\\Testcases.xlsx'

During handling of the above exception, another exception occurred:

Traceback (most recent call last):
  File "f:\GitRepo\auto_interface_test\basic\RunTestcase.py", line 192, in runTestcase
    self.testcases.writeTestResult(apiSheet, rowNo=index, colsNo="api", testResult=("failed",res.text))
  File "f:\GitRepo\auto_interface_test\basic\Testcase.py", line 48, in writeTestResult
    print(u"写excel时发生异常,",+traceback.print_exc())
TypeError: bad operand type for unary +: 'NoneType'

2020-04-07 15:36:52,135 - f:\GitRepo\auto_interface_test\basic\RunTestcase.py[line:202] - ERROR: 出现异常Traceback (most recent call last):
  File "f:\GitRepo\auto_interface_test\basic\RunTestcase.py", line 141, in runTestcase
    dataSheet = self.testcases.operateExcel.getSheetByName(dataSheetName)
  File "f:\GitRepo\auto_interface_test\util\OperateExcel.py", line 31, in getSheetByName
    raise e
  File "f:\GitRepo\auto_interface_test\util\OperateExcel.py", line 28, in getSheetByName
    sheet = self.workbook.get_sheet_by_name(sheetName)
  File "E:\Python37\Lib\site-packages\openpyxl\compat\__init__.py", line 38, in new_func1
    return func1(*args, **kwargs)
  File "E:\Python37\Lib\site-packages\openpyxl\workbook\workbook.py", line 263, in get_sheet_by_name
    return self[name]
  File "E:\Python37\Lib\site-packages\openpyxl\workbook\workbook.py", line 289, in __getitem__
    raise KeyError("Worksheet {0} does not exist.".format(key))
KeyError: 'Worksheet y does not exist.'

2020-04-07 15:37:41,475 - f:\GitRepo\auto_interface_test\basic\RunTestcase.py[line:202] - ERROR: 出现异常Traceback (most recent call last):
  File "f:\GitRepo\auto_interface_test\basic\RunTestcase.py", line 141, in runTestcase
    dataSheet = self.testcases.operateExcel.getSheetByName(dataSheetName)
  File "f:\GitRepo\auto_interface_test\util\OperateExcel.py", line 31, in getSheetByName
    raise e
  File "f:\GitRepo\auto_interface_test\util\OperateExcel.py", line 28, in getSheetByName
    sheet = self.workbook.get_sheet_by_name(sheetName)
  File "E:\Python37\Lib\site-packages\openpyxl\compat\__init__.py", line 38, in new_func1
    return func1(*args, **kwargs)
  File "E:\Python37\Lib\site-packages\openpyxl\workbook\workbook.py", line 263, in get_sheet_by_name
    return self[name]
  File "E:\Python37\Lib\site-packages\openpyxl\workbook\workbook.py", line 289, in __getitem__
    raise KeyError("Worksheet {0} does not exist.".format(key))
KeyError: 'Worksheet None does not exist.'

2020-04-07 15:48:42,762 - f:\GitRepo\auto_interface_test\basic\RunTestcase.py[line:202] - ERROR: 出现异常Traceback (most recent call last):
  File "f:\GitRepo\auto_interface_test\basic\Testcase.py", line 44, in writeTestResult
    rowNo=rowNo, colsNo=colsDict[colsNo][1], style=colorDict[testResult[0]])
  File "f:\GitRepo\auto_interface_test\util\OperateExcel.py", line 127, in writeCell
    raise e
  File "f:\GitRepo\auto_interface_test\util\OperateExcel.py", line 124, in writeCell
    font = Font(color=self.RGBDict[style])
  File "E:\Python37\Lib\site-packages\openpyxl\styles\fonts.py", line 91, in __init__
    self.color = color
  File "E:\Python37\Lib\site-packages\openpyxl\styles\colors.py", line 134, in __set__
    value = Color(rgb=value)
  File "E:\Python37\Lib\site-packages\openpyxl\styles\colors.py", line 94, in __init__
    self.rgb = rgb
  File "E:\Python37\Lib\site-packages\openpyxl\styles\colors.py", line 62, in __set__
    raise ValueError("Colors must be aRGB hex values")
ValueError: Colors must be aRGB hex values

During handling of the above exception, another exception occurred:

Traceback (most recent call last):
  File "f:\GitRepo\auto_interface_test\basic\RunTestcase.py", line 196, in runTestcase
    self.testcases.writeTestResult(apiSheet, rowNo=index, colsNo="dataSheet", testResult=("none","none"))
  File "f:\GitRepo\auto_interface_test\basic\Testcase.py", line 48, in writeTestResult
    print(u"写excel时发生异常,",+traceback.print_exc())
TypeError: bad operand type for unary +: 'NoneType'

2020-04-07 15:50:47,309 - f:\GitRepo\auto_interface_test\basic\RunTestcase.py[line:202] - ERROR: 出现异常Traceback (most recent call last):
  File "f:\GitRepo\auto_interface_test\basic\RunTestcase.py", line 184, in runTestcase
    if (checkData in res.text):
AttributeError: 'str' object has no attribute 'text'

2020-04-07 15:50:51,641 - f:\GitRepo\auto_interface_test\basic\RunTestcase.py[line:202] - ERROR: 出现异常Traceback (most recent call last):
  File "f:\GitRepo\auto_interface_test\basic\RunTestcase.py", line 184, in runTestcase
    if (checkData in res.text):
AttributeError: 'str' object has no attribute 'text'

2020-04-07 15:51:05,243 - f:\GitRepo\auto_interface_test\basic\RunTestcase.py[line:202] - ERROR: 出现异常Traceback (most recent call last):
  File "f:\GitRepo\auto_interface_test\basic\RunTestcase.py", line 184, in runTestcase
    if (checkData in res.text):
AttributeError: 'str' object has no attribute 'text'

2020-04-07 15:54:40,366 - f:\GitRepo\auto_interface_test\basic\RunTestcase.py[line:202] - ERROR: 出现异常Traceback (most recent call last):
  File "f:\GitRepo\auto_interface_test\basic\Testcase.py", line 41, in writeTestResult
    self.operateExcel.writeCellCurrentTime(sheetObj,rowNo=rowNo,colsNo=colsDict[colsNo][0])
  File "f:\GitRepo\auto_interface_test\util\OperateExcel.py", line 147, in writeCellCurrentTime
    raise e
  File "f:\GitRepo\auto_interface_test\util\OperateExcel.py", line 145, in writeCellCurrentTime
    self.workbook.save(self.excelFile)
  File "E:\Python37\Lib\site-packages\openpyxl\workbook\workbook.py", line 408, in save
    save_workbook(self, filename)
  File "E:\Python37\Lib\site-packages\openpyxl\writer\excel.py", line 291, in save_workbook
    archive = ZipFile(filename, 'w', ZIP_DEFLATED, allowZip64=True)
  File "E:\Python37\lib\zipfile.py", line 1204, in __init__
    self.fp = io.open(file, filemode)
PermissionError: [Errno 13] Permission denied: 'f:\\GitRepo\\auto_interface_test\\testcase\\Testcases.xlsx'

During handling of the above exception, another exception occurred:

Traceback (most recent call last):
  File "f:\GitRepo\auto_interface_test\basic\RunTestcase.py", line 188, in runTestcase
    self.testcases.writeTestResult(apiSheet, rowNo=index, colsNo="api", testResult=("pass",res.text))
  File "f:\GitRepo\auto_interface_test\basic\Testcase.py", line 48, in writeTestResult
    print(u"写excel时发生异常,",+traceback.print_exc())
TypeError: bad operand type for unary +: 'NoneType'

2020-04-07 16:03:25,753 - f:\GitRepo\auto_interface_test\basic\RunTestcase.py[line:202] - ERROR: 出现异常Traceback (most recent call last):
  File "f:\GitRepo\auto_interface_test\basic\Testcase.py", line 41, in writeTestResult
    self.operateExcel.writeCellCurrentTime(sheetObj,rowNo=rowNo,colsNo=colsDict[colsNo][0])
  File "f:\GitRepo\auto_interface_test\util\OperateExcel.py", line 147, in writeCellCurrentTime
    raise e
  File "f:\GitRepo\auto_interface_test\util\OperateExcel.py", line 145, in writeCellCurrentTime
    self.workbook.save(self.excelFile)
  File "E:\Python37\Lib\site-packages\openpyxl\workbook\workbook.py", line 408, in save
    save_workbook(self, filename)
  File "E:\Python37\Lib\site-packages\openpyxl\writer\excel.py", line 291, in save_workbook
    archive = ZipFile(filename, 'w', ZIP_DEFLATED, allowZip64=True)
  File "E:\Python37\lib\zipfile.py", line 1204, in __init__
    self.fp = io.open(file, filemode)
PermissionError: [Errno 13] Permission denied: 'f:\\GitRepo\\auto_interface_test\\testcase\\Testcases.xlsx'

During handling of the above exception, another exception occurred:

Traceback (most recent call last):
  File "f:\GitRepo\auto_interface_test\basic\RunTestcase.py", line 188, in runTestcase
    self.testcases.writeTestResult(apiSheet, rowNo=index, colsNo="api", testResult=("pass",res.text))
  File "f:\GitRepo\auto_interface_test\basic\Testcase.py", line 48, in writeTestResult
    print(u"写excel时发生异常,",+traceback.print_exc())
TypeError: bad operand type for unary +: 'NoneType'

2020-04-07 16:17:17,410 - f:\GitRepo\auto_interface_test\basic\RunTestcase.py[line:202] - ERROR: 出现异常Traceback (most recent call last):
  File "f:\GitRepo\auto_interface_test\basic\Testcase.py", line 41, in writeTestResult
    self.operateExcel.writeCellCurrentTime(sheetObj,rowNo=rowNo,colsNo=colsDict[colsNo][0])
  File "f:\GitRepo\auto_interface_test\util\OperateExcel.py", line 147, in writeCellCurrentTime
    raise e
  File "f:\GitRepo\auto_interface_test\util\OperateExcel.py", line 145, in writeCellCurrentTime
    self.workbook.save(self.excelFile)
  File "E:\Python37\Lib\site-packages\openpyxl\workbook\workbook.py", line 408, in save
    save_workbook(self, filename)
  File "E:\Python37\Lib\site-packages\openpyxl\writer\excel.py", line 291, in save_workbook
    archive = ZipFile(filename, 'w', ZIP_DEFLATED, allowZip64=True)
  File "E:\Python37\lib\zipfile.py", line 1204, in __init__
    self.fp = io.open(file, filemode)
PermissionError: [Errno 13] Permission denied: 'f:\\GitRepo\\auto_interface_test\\testcase\\Testcases.xlsx'

During handling of the above exception, another exception occurred:

Traceback (most recent call last):
  File "f:\GitRepo\auto_interface_test\basic\RunTestcase.py", line 188, in runTestcase
    self.testcases.writeTestResult(apiSheet, rowNo=index, colsNo="api", testResult=("pass",res.text))
  File "f:\GitRepo\auto_interface_test\basic\Testcase.py", line 48, in writeTestResult
    print(u"写excel时发生异常,",+traceback.print_exc())
TypeError: bad operand type for unary +: 'NoneType'

2020-04-07 16:44:47,812 - f:\GitRepo\auto_interface_test\basic\RunTestcase.py[line:201] - ERROR: 出现异常Traceback (most recent call last):
  File "f:\GitRepo\auto_interface_test\basic\Testcase.py", line 41, in writeTestResult
    self.operateExcel.writeCellCurrentTime(sheetObj,rowNo=rowNo,colsNo=colsDict[colsNo][0])
  File "f:\GitRepo\auto_interface_test\util\OperateExcel.py", line 147, in writeCellCurrentTime
    raise e
  File "f:\GitRepo\auto_interface_test\util\OperateExcel.py", line 145, in writeCellCurrentTime
    self.workbook.save(self.excelFile)
  File "E:\Python37\Lib\site-packages\openpyxl\workbook\workbook.py", line 408, in save
    save_workbook(self, filename)
  File "E:\Python37\Lib\site-packages\openpyxl\writer\excel.py", line 291, in save_workbook
    archive = ZipFile(filename, 'w', ZIP_DEFLATED, allowZip64=True)
  File "E:\Python37\lib\zipfile.py", line 1204, in __init__
    self.fp = io.open(file, filemode)
PermissionError: [Errno 13] Permission denied: 'f:\\GitRepo\\auto_interface_test\\testcase\\Testcases.xlsx'

During handling of the above exception, another exception occurred:

Traceback (most recent call last):
  File "f:\GitRepo\auto_interface_test\basic\RunTestcase.py", line 187, in runTestcase
    self.testcases.writeTestResult(apiSheet, rowNo=index, colsNo="api", testResult=("pass",res.text))
  File "f:\GitRepo\auto_interface_test\basic\Testcase.py", line 48, in writeTestResult
    print(u"写excel时发生异常,",+traceback.print_exc())
TypeError: bad operand type for unary +: 'NoneType'

2020-04-07 16:48:49,759 - f:\GitRepo\auto_interface_test\basic\RunTestcase.py[line:201] - ERROR: 出现异常Traceback (most recent call last):
  File "f:\GitRepo\auto_interface_test\basic\RunTestcase.py", line 143, in runTestcase
    result = self.dataDrivenFun(apiRow, dataSheet)
  File "f:\GitRepo\auto_interface_test\basic\RunTestcase.py", line 97, in dataDrivenFun
    raise e
  File "f:\GitRepo\auto_interface_test\basic\RunTestcase.py", line 68, in dataDrivenFun
    res = self.ir.main_req(data_method, url, data_requestData, data_header)
UnboundLocalError: local variable 'data_method' referenced before assignment

2020-04-07 16:56:22,565 - f:\GitRepo\auto_interface_test\basic\RunTestcase.py[line:201] - ERROR: 出现异常Traceback (most recent call last):
  File "f:\GitRepo\auto_interface_test\basic\Testcase.py", line 41, in writeTestResult
    self.operateExcel.writeCellCurrentTime(sheetObj,rowNo=rowNo,colsNo=colsDict[colsNo][0])
  File "f:\GitRepo\auto_interface_test\util\OperateExcel.py", line 147, in writeCellCurrentTime
    raise e
  File "f:\GitRepo\auto_interface_test\util\OperateExcel.py", line 145, in writeCellCurrentTime
    self.workbook.save(self.excelFile)
  File "E:\Python37\Lib\site-packages\openpyxl\workbook\workbook.py", line 408, in save
    save_workbook(self, filename)
  File "E:\Python37\Lib\site-packages\openpyxl\writer\excel.py", line 291, in save_workbook
    archive = ZipFile(filename, 'w', ZIP_DEFLATED, allowZip64=True)
  File "E:\Python37\lib\zipfile.py", line 1204, in __init__
    self.fp = io.open(file, filemode)
PermissionError: [Errno 13] Permission denied: 'f:\\GitRepo\\auto_interface_test\\testcase\\Testcases.xlsx'

During handling of the above exception, another exception occurred:

Traceback (most recent call last):
  File "f:\GitRepo\auto_interface_test\basic\RunTestcase.py", line 187, in runTestcase
    self.testcases.writeTestResult(apiSheet, rowNo=index, colsNo="api", testResult=("pass",res.text))
  File "f:\GitRepo\auto_interface_test\basic\Testcase.py", line 48, in writeTestResult
    print(u"写excel时发生异常,",+traceback.print_exc())
TypeError: bad operand type for unary +: 'NoneType'

2020-04-07 16:59:08,934 - f:\GitRepo\auto_interface_test\basic\RunTestcase.py[line:201] - ERROR: 出现异常Traceback (most recent call last):
  File "f:\GitRepo\auto_interface_test\basic\RunTestcase.py", line 183, in runTestcase
    if (checkData in res.text):
TypeError: 'in <string>' requires string as left operand, not int

2020-04-07 17:00:04,968 - f:\GitRepo\auto_interface_test\basic\RunTestcase.py[line:201] - ERROR: 出现异常Traceback (most recent call last):
  File "f:\GitRepo\auto_interface_test\basic\RunTestcase.py", line 183, in runTestcase
    if (checkData.toString() in res.text):
AttributeError: 'str' object has no attribute 'toString'

2020-04-07 17:01:20,642 - f:\GitRepo\auto_interface_test\basic\RunTestcase.py[line:201] - ERROR: 出现异常Traceback (most recent call last):
  File "f:\GitRepo\auto_interface_test\basic\Testcase.py", line 41, in writeTestResult
    self.operateExcel.writeCellCurrentTime(sheetObj,rowNo=rowNo,colsNo=colsDict[colsNo][0])
  File "f:\GitRepo\auto_interface_test\util\OperateExcel.py", line 147, in writeCellCurrentTime
    raise e
  File "f:\GitRepo\auto_interface_test\util\OperateExcel.py", line 145, in writeCellCurrentTime
    self.workbook.save(self.excelFile)
  File "E:\Python37\Lib\site-packages\openpyxl\workbook\workbook.py", line 408, in save
    save_workbook(self, filename)
  File "E:\Python37\Lib\site-packages\openpyxl\writer\excel.py", line 291, in save_workbook
    archive = ZipFile(filename, 'w', ZIP_DEFLATED, allowZip64=True)
  File "E:\Python37\lib\zipfile.py", line 1204, in __init__
    self.fp = io.open(file, filemode)
PermissionError: [Errno 13] Permission denied: 'f:\\GitRepo\\auto_interface_test\\testcase\\Testcases.xlsx'

During handling of the above exception, another exception occurred:

Traceback (most recent call last):
  File "f:\GitRepo\auto_interface_test\basic\RunTestcase.py", line 187, in runTestcase
    self.testcases.writeTestResult(apiSheet, rowNo=index, colsNo="api", testResult=("pass",res.text))
  File "f:\GitRepo\auto_interface_test\basic\Testcase.py", line 48, in writeTestResult
    print(u"写excel时发生异常,",+traceback.print_exc())
TypeError: bad operand type for unary +: 'NoneType'

2020-04-07 17:01:22,614 - f:\GitRepo\auto_interface_test\basic\RunTestcase.py[line:201] - ERROR: 出现异常Traceback (most recent call last):
  File "f:\GitRepo\auto_interface_test\basic\Testcase.py", line 41, in writeTestResult
    self.operateExcel.writeCellCurrentTime(sheetObj,rowNo=rowNo,colsNo=colsDict[colsNo][0])
  File "f:\GitRepo\auto_interface_test\util\OperateExcel.py", line 147, in writeCellCurrentTime
    raise e
  File "f:\GitRepo\auto_interface_test\util\OperateExcel.py", line 145, in writeCellCurrentTime
    self.workbook.save(self.excelFile)
  File "E:\Python37\Lib\site-packages\openpyxl\workbook\workbook.py", line 408, in save
    save_workbook(self, filename)
  File "E:\Python37\Lib\site-packages\openpyxl\writer\excel.py", line 291, in save_workbook
    archive = ZipFile(filename, 'w', ZIP_DEFLATED, allowZip64=True)
  File "E:\Python37\lib\zipfile.py", line 1204, in __init__
    self.fp = io.open(file, filemode)
PermissionError: [Errno 13] Permission denied: 'f:\\GitRepo\\auto_interface_test\\testcase\\Testcases.xlsx'

During handling of the above exception, another exception occurred:

Traceback (most recent call last):
  File "f:\GitRepo\auto_interface_test\basic\RunTestcase.py", line 187, in runTestcase
    self.testcases.writeTestResult(apiSheet, rowNo=index, colsNo="api", testResult=("pass",res.text))
  File "f:\GitRepo\auto_interface_test\basic\Testcase.py", line 48, in writeTestResult
    print(u"写excel时发生异常,",+traceback.print_exc())
TypeError: bad operand type for unary +: 'NoneType'

2020-04-07 17:29:55,079 - f:/GitRepo/auto_interface_test/util/Log.py[line:42] - WARNING: 警告
2020-04-07 17:29:55,080 - f:/GitRepo/auto_interface_test/util/Log.py[line:43] - ERROR: 报错
2020-04-07 17:29:55,080 - f:/GitRepo/auto_interface_test/util/Log.py[line:44] - CRITICAL: 严重
