2020-04-10 14:25:38,585 - f:\GitRepo\auto_interface_test\basic\RunTestcase.py[line:116] - INFO: 接口用例：'接口用例'开始执行
2020-04-10 14:25:40,234 - f:\GitRepo\auto_interface_test\basic\RunTestcase.py[line:185] - INFO: 接口：测试接口1执行成功
2020-04-10 14:25:40,498 - f:\GitRepo\auto_interface_test\basic\RunTestcase.py[line:189] - INFO: 接口：测试接口2执行失败
2020-04-10 14:25:40,549 - f:\GitRepo\auto_interface_test\basic\RunTestcase.py[line:193] - INFO: 接口：测试接口3未执行
2020-04-10 14:25:40,603 - f:\GitRepo\auto_interface_test\basic\RunTestcase.py[line:137] - INFO: ***********调用数据驱动************
2020-04-10 14:25:40,604 - f:\GitRepo\auto_interface_test\basic\RunTestcase.py[line:34] - INFO: 开始执行用例""adWords":"""
2020-04-10 14:25:40,736 - f:\GitRepo\auto_interface_test\basic\RunTestcase.py[line:82] - INFO: 数据："adWords":""执行成功
2020-04-10 14:25:40,787 - f:\GitRepo\auto_interface_test\basic\RunTestcase.py[line:34] - INFO: 开始执行用例"adWords"
2020-04-10 14:25:40,910 - f:\GitRepo\auto_interface_test\basic\RunTestcase.py[line:82] - INFO: 数据：adWords执行成功
2020-04-10 14:25:41,014 - f:\GitRepo\auto_interface_test\basic\RunTestcase.py[line:34] - INFO: 开始执行用例"adWords"
2020-04-10 14:25:41,153 - f:\GitRepo\auto_interface_test\basic\RunTestcase.py[line:82] - INFO: 数据：adWords执行成功
2020-04-10 14:25:41,206 - f:\GitRepo\auto_interface_test\basic\RunTestcase.py[line:34] - INFO: 开始执行用例"adWords123"
2020-04-10 14:25:41,429 - f:\GitRepo\auto_interface_test\basic\RunTestcase.py[line:86] - INFO: 数据：adWords123执行失败
2020-04-10 14:25:41,481 - f:\GitRepo\auto_interface_test\basic\RunTestcase.py[line:150] - INFO: 接口：测试接口4执行失败
2020-04-10 14:25:41,583 - f:\GitRepo\auto_interface_test\basic\RunTestcase.py[line:197] - INFO: 接口用例：'接口用例'执行完成
2020-04-10 14:29:52,917 - f:\GitRepo\auto_interface_test\basic\RunTestcase.py[line:116] - INFO: 接口用例：'接口用例'开始执行
2020-04-10 14:29:53,042 - f:\GitRepo\auto_interface_test\basic\RunTestcase.py[line:185] - INFO: 接口：测试接口1执行成功
2020-04-10 14:29:53,208 - f:\GitRepo\auto_interface_test\basic\RunTestcase.py[line:189] - INFO: 接口：测试接口2执行失败
2020-04-10 14:29:53,259 - f:\GitRepo\auto_interface_test\basic\RunTestcase.py[line:193] - INFO: 接口：测试接口3未执行
2020-04-10 14:29:53,310 - f:\GitRepo\auto_interface_test\basic\RunTestcase.py[line:137] - INFO: ***********调用数据驱动************
2020-04-10 14:29:53,311 - f:\GitRepo\auto_interface_test\basic\RunTestcase.py[line:34] - INFO: 开始执行用例""adWords":"""
2020-04-10 14:29:53,431 - f:\GitRepo\auto_interface_test\basic\RunTestcase.py[line:82] - INFO: 数据："adWords":""执行成功
2020-04-10 14:29:53,485 - f:\GitRepo\auto_interface_test\basic\RunTestcase.py[line:34] - INFO: 开始执行用例"adWords"
2020-04-10 14:29:53,630 - f:\GitRepo\auto_interface_test\basic\RunTestcase.py[line:82] - INFO: 数据：adWords执行成功
2020-04-10 14:29:53,733 - f:\GitRepo\auto_interface_test\basic\RunTestcase.py[line:34] - INFO: 开始执行用例"adWords"
2020-04-10 14:29:53,861 - f:\GitRepo\auto_interface_test\basic\RunTestcase.py[line:82] - INFO: 数据：adWords执行成功
2020-04-10 14:29:53,914 - f:\GitRepo\auto_interface_test\basic\RunTestcase.py[line:34] - INFO: 开始执行用例"adWords123"
2020-04-10 14:29:54,046 - f:\GitRepo\auto_interface_test\basic\RunTestcase.py[line:86] - INFO: 数据：adWords123执行失败
2020-04-10 14:29:54,098 - f:\GitRepo\auto_interface_test\basic\RunTestcase.py[line:150] - INFO: 接口：测试接口4执行失败
2020-04-10 14:29:54,201 - f:\GitRepo\auto_interface_test\basic\RunTestcase.py[line:197] - INFO: 接口用例：'接口用例'执行完成
2020-04-10 14:50:42,640 - f:\GitRepo\auto_interface_test\basic\RunTestcase.py[line:116] - INFO: 接口用例：'接口用例'开始执行
2020-04-10 14:50:42,782 - f:\GitRepo\auto_interface_test\basic\RunTestcase.py[line:185] - INFO: 接口：测试接口1执行成功
2020-04-10 14:50:42,956 - f:\GitRepo\auto_interface_test\basic\RunTestcase.py[line:189] - INFO: 接口：测试接口2执行失败
2020-04-10 14:50:43,011 - f:\GitRepo\auto_interface_test\basic\RunTestcase.py[line:193] - INFO: 接口：测试接口3未执行
2020-04-10 14:50:43,070 - f:\GitRepo\auto_interface_test\basic\RunTestcase.py[line:137] - INFO: ***********调用数据驱动************
2020-04-10 14:50:43,070 - f:\GitRepo\auto_interface_test\basic\RunTestcase.py[line:34] - INFO: 开始执行用例""adWords":"""
2020-04-10 14:50:43,198 - f:\GitRepo\auto_interface_test\basic\RunTestcase.py[line:82] - INFO: 数据："adWords":""执行成功
2020-04-10 14:50:43,254 - f:\GitRepo\auto_interface_test\basic\RunTestcase.py[line:34] - INFO: 开始执行用例"adWords"
2020-04-10 14:50:43,384 - f:\GitRepo\auto_interface_test\basic\RunTestcase.py[line:82] - INFO: 数据：adWords执行成功
2020-04-10 14:50:43,490 - f:\GitRepo\auto_interface_test\basic\RunTestcase.py[line:34] - INFO: 开始执行用例"adWords"
2020-04-10 14:50:43,596 - f:\GitRepo\auto_interface_test\basic\RunTestcase.py[line:82] - INFO: 数据：adWords执行成功
2020-04-10 14:50:43,654 - f:\GitRepo\auto_interface_test\basic\RunTestcase.py[line:34] - INFO: 开始执行用例"adWords123"
2020-04-10 14:50:43,771 - f:\GitRepo\auto_interface_test\basic\RunTestcase.py[line:86] - INFO: 数据：adWords123执行失败
2020-04-10 14:50:43,824 - f:\GitRepo\auto_interface_test\basic\RunTestcase.py[line:150] - INFO: 接口：测试接口4执行失败
2020-04-10 14:50:43,933 - f:\GitRepo\auto_interface_test\basic\RunTestcase.py[line:197] - INFO: 接口用例：'接口用例'执行完成
2020-04-10 15:01:25,505 - f:\GitRepo\auto_interface_test\basic\RunTestcase.py[line:116] - INFO: 接口用例：'接口用例'开始执行
2020-04-10 15:01:25,706 - f:\GitRepo\auto_interface_test\basic\RunTestcase.py[line:185] - INFO: 接口：测试接口1执行成功
2020-04-10 15:01:25,896 - f:\GitRepo\auto_interface_test\basic\RunTestcase.py[line:189] - INFO: 接口：测试接口2执行失败
2020-04-10 15:01:25,951 - f:\GitRepo\auto_interface_test\basic\RunTestcase.py[line:193] - INFO: 接口：测试接口3未执行
2020-04-10 15:01:26,005 - f:\GitRepo\auto_interface_test\basic\RunTestcase.py[line:137] - INFO: ***********调用数据驱动************
2020-04-10 15:01:26,006 - f:\GitRepo\auto_interface_test\basic\RunTestcase.py[line:34] - INFO: 开始执行用例""adWords":"""
2020-04-10 15:01:26,137 - f:\GitRepo\auto_interface_test\basic\RunTestcase.py[line:82] - INFO: 数据："adWords":""执行成功
2020-04-10 15:01:26,190 - f:\GitRepo\auto_interface_test\basic\RunTestcase.py[line:34] - INFO: 开始执行用例"adWords"
2020-04-10 15:01:26,319 - f:\GitRepo\auto_interface_test\basic\RunTestcase.py[line:82] - INFO: 数据：adWords执行成功
2020-04-10 15:01:26,427 - f:\GitRepo\auto_interface_test\basic\RunTestcase.py[line:34] - INFO: 开始执行用例"adWords"
2020-04-10 15:01:26,564 - f:\GitRepo\auto_interface_test\basic\RunTestcase.py[line:82] - INFO: 数据：adWords执行成功
2020-04-10 15:01:26,618 - f:\GitRepo\auto_interface_test\basic\RunTestcase.py[line:34] - INFO: 开始执行用例"adWords123"
2020-04-10 15:01:26,759 - f:\GitRepo\auto_interface_test\basic\RunTestcase.py[line:86] - INFO: 数据：adWords123执行失败
2020-04-10 15:01:26,812 - f:\GitRepo\auto_interface_test\basic\RunTestcase.py[line:150] - INFO: 接口：测试接口4执行失败
2020-04-10 15:01:26,919 - f:\GitRepo\auto_interface_test\basic\RunTestcase.py[line:197] - INFO: 接口用例：'接口用例'执行完成
2020-04-10 15:03:20,435 - f:\GitRepo\auto_interface_test\basic\RunTestcase.py[line:116] - INFO: 接口用例：'接口用例'开始执行
2020-04-10 15:03:20,566 - f:\GitRepo\auto_interface_test\basic\RunTestcase.py[line:185] - INFO: 接口：测试接口1执行成功
2020-04-10 15:03:20,748 - f:\GitRepo\auto_interface_test\basic\RunTestcase.py[line:189] - INFO: 接口：测试接口2执行失败
2020-04-10 15:03:20,802 - f:\GitRepo\auto_interface_test\basic\RunTestcase.py[line:193] - INFO: 接口：测试接口3未执行
2020-04-10 15:03:20,858 - f:\GitRepo\auto_interface_test\basic\RunTestcase.py[line:137] - INFO: ***********调用数据驱动************
2020-04-10 15:03:20,858 - f:\GitRepo\auto_interface_test\basic\RunTestcase.py[line:34] - INFO: 开始执行用例""adWords":"""
2020-04-10 15:03:20,983 - f:\GitRepo\auto_interface_test\basic\RunTestcase.py[line:82] - INFO: 数据："adWords":""执行成功
2020-04-10 15:03:21,035 - f:\GitRepo\auto_interface_test\basic\RunTestcase.py[line:34] - INFO: 开始执行用例"adWords"
2020-04-10 15:03:21,164 - f:\GitRepo\auto_interface_test\basic\RunTestcase.py[line:82] - INFO: 数据：adWords执行成功
2020-04-10 15:03:21,277 - f:\GitRepo\auto_interface_test\basic\RunTestcase.py[line:34] - INFO: 开始执行用例"adWords"
2020-04-10 15:03:21,386 - f:\GitRepo\auto_interface_test\basic\RunTestcase.py[line:82] - INFO: 数据：adWords执行成功
2020-04-10 15:03:21,436 - f:\GitRepo\auto_interface_test\basic\RunTestcase.py[line:34] - INFO: 开始执行用例"adWords123"
2020-04-10 15:03:21,568 - f:\GitRepo\auto_interface_test\basic\RunTestcase.py[line:86] - INFO: 数据：adWords123执行失败
2020-04-10 15:03:21,624 - f:\GitRepo\auto_interface_test\basic\RunTestcase.py[line:150] - INFO: 接口：测试接口4执行失败
2020-04-10 15:03:21,731 - f:\GitRepo\auto_interface_test\basic\RunTestcase.py[line:197] - INFO: 接口用例：'接口用例'执行完成
2020-04-10 15:03:35,397 - f:\GitRepo\auto_interface_test\basic\RunTestcase.py[line:116] - INFO: 接口用例：'接口用例'开始执行
2020-04-10 15:03:35,530 - f:\GitRepo\auto_interface_test\basic\RunTestcase.py[line:185] - INFO: 接口：测试接口1执行成功
2020-04-10 15:03:35,703 - f:\GitRepo\auto_interface_test\basic\RunTestcase.py[line:189] - INFO: 接口：测试接口2执行失败
2020-04-10 15:03:35,754 - f:\GitRepo\auto_interface_test\basic\RunTestcase.py[line:193] - INFO: 接口：测试接口3未执行
2020-04-10 15:03:35,805 - f:\GitRepo\auto_interface_test\basic\RunTestcase.py[line:137] - INFO: ***********调用数据驱动************
2020-04-10 15:03:35,806 - f:\GitRepo\auto_interface_test\basic\RunTestcase.py[line:34] - INFO: 开始执行用例""adWords":"""
2020-04-10 15:03:35,950 - f:\GitRepo\auto_interface_test\basic\RunTestcase.py[line:82] - INFO: 数据："adWords":""执行成功
2020-04-10 15:03:36,002 - f:\GitRepo\auto_interface_test\basic\RunTestcase.py[line:34] - INFO: 开始执行用例"adWords"
2020-04-10 15:03:36,272 - f:\GitRepo\auto_interface_test\basic\RunTestcase.py[line:82] - INFO: 数据：adWords执行成功
2020-04-10 15:03:36,420 - f:\GitRepo\auto_interface_test\basic\RunTestcase.py[line:34] - INFO: 开始执行用例"adWords"
2020-04-10 15:03:36,549 - f:\GitRepo\auto_interface_test\basic\RunTestcase.py[line:82] - INFO: 数据：adWords执行成功
2020-04-10 15:03:36,600 - f:\GitRepo\auto_interface_test\basic\RunTestcase.py[line:34] - INFO: 开始执行用例"adWords123"
2020-04-10 15:03:36,729 - f:\GitRepo\auto_interface_test\basic\RunTestcase.py[line:86] - INFO: 数据：adWords123执行失败
2020-04-10 15:03:36,781 - f:\GitRepo\auto_interface_test\basic\RunTestcase.py[line:150] - INFO: 接口：测试接口4执行失败
2020-04-10 15:03:36,887 - f:\GitRepo\auto_interface_test\basic\RunTestcase.py[line:197] - INFO: 接口用例：'接口用例'执行完成
2020-04-10 15:18:40,372 - f:\GitRepo\auto_interface_test\basic\RunTestcase.py[line:116] - INFO: 接口用例：'接口用例'开始执行
2020-04-10 15:18:40,575 - f:\GitRepo\auto_interface_test\basic\RunTestcase.py[line:185] - INFO: 接口：测试接口1执行成功
2020-04-10 15:18:40,751 - f:\GitRepo\auto_interface_test\basic\RunTestcase.py[line:189] - INFO: 接口：测试接口2执行失败
2020-04-10 15:18:40,802 - f:\GitRepo\auto_interface_test\basic\RunTestcase.py[line:193] - INFO: 接口：测试接口3未执行
2020-04-10 15:18:40,851 - f:\GitRepo\auto_interface_test\basic\RunTestcase.py[line:137] - INFO: ***********调用数据驱动************
2020-04-10 15:18:40,852 - f:\GitRepo\auto_interface_test\basic\RunTestcase.py[line:34] - INFO: 开始执行用例""adWords":"""
2020-04-10 15:18:40,972 - f:\GitRepo\auto_interface_test\basic\RunTestcase.py[line:82] - INFO: 数据："adWords":""执行成功
2020-04-10 15:18:41,023 - f:\GitRepo\auto_interface_test\basic\RunTestcase.py[line:34] - INFO: 开始执行用例"adWords"
2020-04-10 15:18:41,129 - f:\GitRepo\auto_interface_test\basic\RunTestcase.py[line:82] - INFO: 数据：adWords执行成功
2020-04-10 15:18:41,230 - f:\GitRepo\auto_interface_test\basic\RunTestcase.py[line:34] - INFO: 开始执行用例"adWords"
2020-04-10 15:18:41,380 - f:\GitRepo\auto_interface_test\basic\RunTestcase.py[line:82] - INFO: 数据：adWords执行成功
2020-04-10 15:18:41,428 - f:\GitRepo\auto_interface_test\basic\RunTestcase.py[line:34] - INFO: 开始执行用例"adWords123"
2020-04-10 15:18:41,563 - f:\GitRepo\auto_interface_test\basic\RunTestcase.py[line:86] - INFO: 数据：adWords123执行失败
2020-04-10 15:18:41,614 - f:\GitRepo\auto_interface_test\basic\RunTestcase.py[line:150] - INFO: 接口：测试接口4执行失败
2020-04-10 15:18:41,710 - f:\GitRepo\auto_interface_test\basic\RunTestcase.py[line:197] - INFO: 接口用例：'接口用例'执行完成
2020-04-10 15:20:54,838 - f:\GitRepo\auto_interface_test\basic\RunTestcase.py[line:116] - INFO: 接口用例：'接口用例'开始执行
2020-04-10 15:20:54,955 - f:\GitRepo\auto_interface_test\basic\RunTestcase.py[line:185] - INFO: 接口：测试接口1执行成功
2020-04-10 15:20:54,963 - f:\GitRepo\auto_interface_test\basic\RunTestcase.py[line:202] - ERROR: 出现异常Traceback (most recent call last):
  File "f:\GitRepo\auto_interface_test\basic\Testcase.py", line 48, in writeTestResult
    self.operateExcel.writeCellCurrentTime(sheetObj,rowNo=rowNo,colsNo=colsDict[colsNo][0])
  File "f:\GitRepo\auto_interface_test\util\OperateExcel.py", line 153, in writeCellCurrentTime
    raise e
  File "f:\GitRepo\auto_interface_test\util\OperateExcel.py", line 151, in writeCellCurrentTime
    self.workbook.save(self.excelFile)
  File "E:\Python37\Lib\site-packages\openpyxl\workbook\workbook.py", line 408, in save
    save_workbook(self, filename)
  File "E:\Python37\Lib\site-packages\openpyxl\writer\excel.py", line 291, in save_workbook
    archive = ZipFile(filename, 'w', ZIP_DEFLATED, allowZip64=True)
  File "E:\Python37\lib\zipfile.py", line 1204, in __init__
    self.fp = io.open(file, filemode)
PermissionError: [Errno 13] Permission denied: 'f:\\GitRepo\\auto_interface_test\\testcase\\Testcases.xlsx'

During handling of the above exception, another exception occurred:

Traceback (most recent call last):
  File "f:\GitRepo\auto_interface_test\basic\RunTestcase.py", line 187, in runTestcase
    self.testcases.writeTestResult(apiSheet, rowNo=index, colsNo="api", testResult=("pass",res.text))
  File "f:\GitRepo\auto_interface_test\basic\Testcase.py", line 55, in writeTestResult
    print(u"写excel时发生异常,",+traceback.print_exc())
TypeError: bad operand type for unary +: 'NoneType'

2020-04-10 15:20:56,995 - f:\GitRepo\auto_interface_test\basic\RunTestcase.py[line:116] - INFO: 接口用例：'接口用例'开始执行
2020-04-10 15:20:57,122 - f:\GitRepo\auto_interface_test\basic\RunTestcase.py[line:185] - INFO: 接口：测试接口1执行成功
2020-04-10 15:20:57,130 - f:\GitRepo\auto_interface_test\basic\RunTestcase.py[line:202] - ERROR: 出现异常Traceback (most recent call last):
  File "f:\GitRepo\auto_interface_test\basic\Testcase.py", line 48, in writeTestResult
    self.operateExcel.writeCellCurrentTime(sheetObj,rowNo=rowNo,colsNo=colsDict[colsNo][0])
  File "f:\GitRepo\auto_interface_test\util\OperateExcel.py", line 153, in writeCellCurrentTime
    raise e
  File "f:\GitRepo\auto_interface_test\util\OperateExcel.py", line 151, in writeCellCurrentTime
    self.workbook.save(self.excelFile)
  File "E:\Python37\Lib\site-packages\openpyxl\workbook\workbook.py", line 408, in save
    save_workbook(self, filename)
  File "E:\Python37\Lib\site-packages\openpyxl\writer\excel.py", line 291, in save_workbook
    archive = ZipFile(filename, 'w', ZIP_DEFLATED, allowZip64=True)
  File "E:\Python37\lib\zipfile.py", line 1204, in __init__
    self.fp = io.open(file, filemode)
PermissionError: [Errno 13] Permission denied: 'f:\\GitRepo\\auto_interface_test\\testcase\\Testcases.xlsx'

During handling of the above exception, another exception occurred:

Traceback (most recent call last):
  File "f:\GitRepo\auto_interface_test\basic\RunTestcase.py", line 187, in runTestcase
    self.testcases.writeTestResult(apiSheet, rowNo=index, colsNo="api", testResult=("pass",res.text))
  File "f:\GitRepo\auto_interface_test\basic\Testcase.py", line 55, in writeTestResult
    print(u"写excel时发生异常,",+traceback.print_exc())
TypeError: bad operand type for unary +: 'NoneType'

2020-04-10 15:21:02,560 - f:\GitRepo\auto_interface_test\basic\RunTestcase.py[line:116] - INFO: 接口用例：'接口用例'开始执行
2020-04-10 15:21:02,704 - f:\GitRepo\auto_interface_test\basic\RunTestcase.py[line:185] - INFO: 接口：测试接口1执行成功
2020-04-10 15:21:02,899 - f:\GitRepo\auto_interface_test\basic\RunTestcase.py[line:189] - INFO: 接口：测试接口2执行失败
2020-04-10 15:21:02,954 - f:\GitRepo\auto_interface_test\basic\RunTestcase.py[line:193] - INFO: 接口：测试接口3未执行
2020-04-10 15:21:03,009 - f:\GitRepo\auto_interface_test\basic\RunTestcase.py[line:137] - INFO: ***********调用数据驱动************
2020-04-10 15:21:03,009 - f:\GitRepo\auto_interface_test\basic\RunTestcase.py[line:34] - INFO: 开始执行用例""adWords":"""
2020-04-10 15:21:03,143 - f:\GitRepo\auto_interface_test\basic\RunTestcase.py[line:82] - INFO: 数据："adWords":""执行成功
2020-04-10 15:21:03,197 - f:\GitRepo\auto_interface_test\basic\RunTestcase.py[line:34] - INFO: 开始执行用例"adWords"
2020-04-10 15:21:03,321 - f:\GitRepo\auto_interface_test\basic\RunTestcase.py[line:82] - INFO: 数据：adWords执行成功
2020-04-10 15:21:03,426 - f:\GitRepo\auto_interface_test\basic\RunTestcase.py[line:34] - INFO: 开始执行用例"adWords"
2020-04-10 15:21:03,553 - f:\GitRepo\auto_interface_test\basic\RunTestcase.py[line:82] - INFO: 数据：adWords执行成功
2020-04-10 15:21:03,604 - f:\GitRepo\auto_interface_test\basic\RunTestcase.py[line:34] - INFO: 开始执行用例"adWords123"
2020-04-10 15:21:03,728 - f:\GitRepo\auto_interface_test\basic\RunTestcase.py[line:86] - INFO: 数据：adWords123执行失败
2020-04-10 15:21:03,801 - f:\GitRepo\auto_interface_test\basic\RunTestcase.py[line:150] - INFO: 接口：测试接口4执行失败
2020-04-10 15:21:03,916 - f:\GitRepo\auto_interface_test\basic\RunTestcase.py[line:197] - INFO: 接口用例：'接口用例'执行完成
2020-04-10 15:28:23,729 - f:\GitRepo\auto_interface_test\basic\RunTestcase.py[line:116] - INFO: 接口用例：'接口用例'开始执行
2020-04-10 15:28:23,876 - f:\GitRepo\auto_interface_test\basic\RunTestcase.py[line:185] - INFO: 接口：测试接口1执行成功
2020-04-10 15:28:24,098 - f:\GitRepo\auto_interface_test\basic\RunTestcase.py[line:189] - INFO: 接口：测试接口2执行失败
2020-04-10 15:28:24,179 - f:\GitRepo\auto_interface_test\basic\RunTestcase.py[line:193] - INFO: 接口：测试接口3未执行
2020-04-10 15:28:24,271 - f:\GitRepo\auto_interface_test\basic\RunTestcase.py[line:137] - INFO: ***********调用数据驱动************
2020-04-10 15:28:24,272 - f:\GitRepo\auto_interface_test\basic\RunTestcase.py[line:34] - INFO: 开始执行用例""adWords":"""
2020-04-10 15:28:24,396 - f:\GitRepo\auto_interface_test\basic\RunTestcase.py[line:82] - INFO: 数据："adWords":""执行成功
2020-04-10 15:28:24,479 - f:\GitRepo\auto_interface_test\basic\RunTestcase.py[line:34] - INFO: 开始执行用例"adWords"
2020-04-10 15:28:24,613 - f:\GitRepo\auto_interface_test\basic\RunTestcase.py[line:82] - INFO: 数据：adWords执行成功
2020-04-10 15:28:24,782 - f:\GitRepo\auto_interface_test\basic\RunTestcase.py[line:34] - INFO: 开始执行用例"adWords"
2020-04-10 15:28:24,923 - f:\GitRepo\auto_interface_test\basic\RunTestcase.py[line:82] - INFO: 数据：adWords执行成功
2020-04-10 15:28:25,008 - f:\GitRepo\auto_interface_test\basic\RunTestcase.py[line:34] - INFO: 开始执行用例"adWords123"
2020-04-10 15:28:25,146 - f:\GitRepo\auto_interface_test\basic\RunTestcase.py[line:86] - INFO: 数据：adWords123执行失败
2020-04-10 15:28:25,232 - f:\GitRepo\auto_interface_test\basic\RunTestcase.py[line:150] - INFO: 接口：测试接口4执行失败
2020-04-10 15:28:25,397 - f:\GitRepo\auto_interface_test\basic\RunTestcase.py[line:197] - INFO: 接口用例：'接口用例'执行完成
2020-04-10 15:57:29,937 - f:\GitRepo\auto_interface_test\basic\RunTestcase.py[line:116] - INFO: 接口用例：'接口用例'开始执行
2020-04-10 15:57:30,094 - f:\GitRepo\auto_interface_test\basic\RunTestcase.py[line:185] - INFO: 接口：测试接口1执行成功
2020-04-10 15:57:30,298 - f:\GitRepo\auto_interface_test\basic\RunTestcase.py[line:189] - INFO: 接口：测试接口2执行失败
2020-04-10 15:57:30,380 - f:\GitRepo\auto_interface_test\basic\RunTestcase.py[line:193] - INFO: 接口：测试接口3未执行
2020-04-10 15:57:30,461 - f:\GitRepo\auto_interface_test\basic\RunTestcase.py[line:137] - INFO: ***********调用数据驱动************
2020-04-10 15:57:30,463 - f:\GitRepo\auto_interface_test\basic\RunTestcase.py[line:34] - INFO: 开始执行用例""adWords":"""
2020-04-10 15:57:30,589 - f:\GitRepo\auto_interface_test\basic\RunTestcase.py[line:82] - INFO: 数据："adWords":""执行成功
2020-04-10 15:57:30,671 - f:\GitRepo\auto_interface_test\basic\RunTestcase.py[line:34] - INFO: 开始执行用例"adWords"
2020-04-10 15:57:30,798 - f:\GitRepo\auto_interface_test\basic\RunTestcase.py[line:82] - INFO: 数据：adWords执行成功
2020-04-10 15:57:30,960 - f:\GitRepo\auto_interface_test\basic\RunTestcase.py[line:34] - INFO: 开始执行用例"adWords"
2020-04-10 15:57:31,299 - f:\GitRepo\auto_interface_test\basic\RunTestcase.py[line:82] - INFO: 数据：adWords执行成功
2020-04-10 15:57:31,384 - f:\GitRepo\auto_interface_test\basic\RunTestcase.py[line:34] - INFO: 开始执行用例"adWords123"
2020-04-10 15:57:31,511 - f:\GitRepo\auto_interface_test\basic\RunTestcase.py[line:86] - INFO: 数据：adWords123执行失败
2020-04-10 15:57:31,596 - f:\GitRepo\auto_interface_test\basic\RunTestcase.py[line:150] - INFO: 接口：测试接口4执行失败
2020-04-10 15:57:31,755 - f:\GitRepo\auto_interface_test\basic\RunTestcase.py[line:197] - INFO: 接口用例：'接口用例'执行完成
2020-04-10 15:59:51,143 - f:\GitRepo\auto_interface_test\basic\RunTestcase.py[line:116] - INFO: 接口用例：'接口用例'开始执行
2020-04-10 15:59:51,270 - f:\GitRepo\auto_interface_test\basic\RunTestcase.py[line:185] - INFO: 接口：测试接口1执行成功
2020-04-10 15:59:51,482 - f:\GitRepo\auto_interface_test\basic\RunTestcase.py[line:189] - INFO: 接口：测试接口2执行失败
2020-04-10 15:59:51,565 - f:\GitRepo\auto_interface_test\basic\RunTestcase.py[line:193] - INFO: 接口：测试接口3未执行
2020-04-10 15:59:51,646 - f:\GitRepo\auto_interface_test\basic\RunTestcase.py[line:137] - INFO: ***********调用数据驱动************
2020-04-10 15:59:51,648 - f:\GitRepo\auto_interface_test\basic\RunTestcase.py[line:34] - INFO: 开始执行用例""adWords":"""
2020-04-10 15:59:51,769 - f:\GitRepo\auto_interface_test\basic\RunTestcase.py[line:82] - INFO: 数据："adWords":""执行成功
2020-04-10 15:59:51,849 - f:\GitRepo\auto_interface_test\basic\RunTestcase.py[line:34] - INFO: 开始执行用例"adWords"
2020-04-10 15:59:51,978 - f:\GitRepo\auto_interface_test\basic\RunTestcase.py[line:82] - INFO: 数据：adWords执行成功
2020-04-10 15:59:52,141 - f:\GitRepo\auto_interface_test\basic\RunTestcase.py[line:34] - INFO: 开始执行用例"adWords"
2020-04-10 15:59:52,270 - f:\GitRepo\auto_interface_test\basic\RunTestcase.py[line:82] - INFO: 数据：adWords执行成功
2020-04-10 15:59:52,404 - f:\GitRepo\auto_interface_test\basic\RunTestcase.py[line:34] - INFO: 开始执行用例"adWords123"
2020-04-10 15:59:52,525 - f:\GitRepo\auto_interface_test\basic\RunTestcase.py[line:86] - INFO: 数据：adWords123执行失败
2020-04-10 15:59:52,606 - f:\GitRepo\auto_interface_test\basic\RunTestcase.py[line:150] - INFO: 接口：测试接口4执行失败
2020-04-10 15:59:52,769 - f:\GitRepo\auto_interface_test\basic\RunTestcase.py[line:197] - INFO: 接口用例：'接口用例'执行完成
2020-04-10 16:04:48,662 - f:\GitRepo\auto_interface_test\basic\RunTestcase.py[line:116] - INFO: 接口用例：'接口用例'开始执行
2020-04-10 16:04:48,823 - f:\GitRepo\auto_interface_test\basic\RunTestcase.py[line:185] - INFO: 接口：测试接口1执行成功
2020-04-10 16:04:49,048 - f:\GitRepo\auto_interface_test\basic\RunTestcase.py[line:189] - INFO: 接口：测试接口2执行失败
2020-04-10 16:04:49,130 - f:\GitRepo\auto_interface_test\basic\RunTestcase.py[line:193] - INFO: 接口：测试接口3未执行
2020-04-10 16:04:49,211 - f:\GitRepo\auto_interface_test\basic\RunTestcase.py[line:137] - INFO: ***********调用数据驱动************
2020-04-10 16:04:49,212 - f:\GitRepo\auto_interface_test\basic\RunTestcase.py[line:34] - INFO: 开始执行用例""adWords":"""
2020-04-10 16:04:49,335 - f:\GitRepo\auto_interface_test\basic\RunTestcase.py[line:82] - INFO: 数据："adWords":""执行成功
2020-04-10 16:04:49,417 - f:\GitRepo\auto_interface_test\basic\RunTestcase.py[line:34] - INFO: 开始执行用例"adWords"
2020-04-10 16:04:49,541 - f:\GitRepo\auto_interface_test\basic\RunTestcase.py[line:82] - INFO: 数据：adWords执行成功
2020-04-10 16:04:49,700 - f:\GitRepo\auto_interface_test\basic\RunTestcase.py[line:34] - INFO: 开始执行用例"adWords"
2020-04-10 16:04:49,835 - f:\GitRepo\auto_interface_test\basic\RunTestcase.py[line:82] - INFO: 数据：adWords执行成功
2020-04-10 16:04:49,919 - f:\GitRepo\auto_interface_test\basic\RunTestcase.py[line:34] - INFO: 开始执行用例"adWords123"
2020-04-10 16:04:50,058 - f:\GitRepo\auto_interface_test\basic\RunTestcase.py[line:86] - INFO: 数据：adWords123执行失败
2020-04-10 16:04:50,138 - f:\GitRepo\auto_interface_test\basic\RunTestcase.py[line:150] - INFO: 接口：测试接口4执行失败
2020-04-10 16:04:50,346 - f:\GitRepo\auto_interface_test\basic\RunTestcase.py[line:197] - INFO: 接口用例：'接口用例'执行完成
2020-04-10 16:08:09,756 - f:\GitRepo\auto_interface_test\basic\RunTestcase.py[line:116] - INFO: 接口用例：'接口用例'开始执行
2020-04-10 16:08:09,939 - f:\GitRepo\auto_interface_test\basic\RunTestcase.py[line:185] - INFO: 接口：测试接口1执行成功
2020-04-10 16:08:10,155 - f:\GitRepo\auto_interface_test\basic\RunTestcase.py[line:189] - INFO: 接口：测试接口2执行失败
2020-04-10 16:08:10,236 - f:\GitRepo\auto_interface_test\basic\RunTestcase.py[line:193] - INFO: 接口：测试接口3未执行
2020-04-10 16:08:10,346 - f:\GitRepo\auto_interface_test\basic\RunTestcase.py[line:137] - INFO: ***********调用数据驱动************
2020-04-10 16:08:10,347 - f:\GitRepo\auto_interface_test\basic\RunTestcase.py[line:34] - INFO: 开始执行用例""adWords":"""
2020-04-10 16:08:10,472 - f:\GitRepo\auto_interface_test\basic\RunTestcase.py[line:82] - INFO: 数据："adWords":""执行成功
2020-04-10 16:08:10,554 - f:\GitRepo\auto_interface_test\basic\RunTestcase.py[line:34] - INFO: 开始执行用例"adWords"
2020-04-10 16:08:10,668 - f:\GitRepo\auto_interface_test\basic\RunTestcase.py[line:82] - INFO: 数据：adWords执行成功
2020-04-10 16:08:10,828 - f:\GitRepo\auto_interface_test\basic\RunTestcase.py[line:34] - INFO: 开始执行用例"adWords"
2020-04-10 16:08:10,954 - f:\GitRepo\auto_interface_test\basic\RunTestcase.py[line:82] - INFO: 数据：adWords执行成功
2020-04-10 16:08:11,036 - f:\GitRepo\auto_interface_test\basic\RunTestcase.py[line:34] - INFO: 开始执行用例"adWords123"
2020-04-10 16:08:11,159 - f:\GitRepo\auto_interface_test\basic\RunTestcase.py[line:86] - INFO: 数据：adWords123执行失败
2020-04-10 16:08:11,254 - f:\GitRepo\auto_interface_test\basic\RunTestcase.py[line:150] - INFO: 接口：测试接口4执行失败
2020-04-10 16:08:11,418 - f:\GitRepo\auto_interface_test\basic\RunTestcase.py[line:197] - INFO: 接口用例：'接口用例'执行完成
2020-04-10 16:09:15,463 - f:\GitRepo\auto_interface_test\basic\RunTestcase.py[line:116] - INFO: 接口用例：'接口用例'开始执行
2020-04-10 16:09:15,600 - f:\GitRepo\auto_interface_test\basic\RunTestcase.py[line:185] - INFO: 接口：测试接口1执行成功
2020-04-10 16:09:15,773 - f:\GitRepo\auto_interface_test\basic\RunTestcase.py[line:189] - INFO: 接口：测试接口2执行失败
2020-04-10 16:09:15,829 - f:\GitRepo\auto_interface_test\basic\RunTestcase.py[line:193] - INFO: 接口：测试接口3未执行
2020-04-10 16:09:15,886 - f:\GitRepo\auto_interface_test\basic\RunTestcase.py[line:137] - INFO: ***********调用数据驱动************
2020-04-10 16:09:15,886 - f:\GitRepo\auto_interface_test\basic\RunTestcase.py[line:34] - INFO: 开始执行用例""adWords":"""
2020-04-10 16:09:15,999 - f:\GitRepo\auto_interface_test\basic\RunTestcase.py[line:82] - INFO: 数据："adWords":""执行成功
2020-04-10 16:09:16,050 - f:\GitRepo\auto_interface_test\basic\RunTestcase.py[line:34] - INFO: 开始执行用例"adWords"
2020-04-10 16:09:16,167 - f:\GitRepo\auto_interface_test\basic\RunTestcase.py[line:82] - INFO: 数据：adWords执行成功
2020-04-10 16:09:16,270 - f:\GitRepo\auto_interface_test\basic\RunTestcase.py[line:34] - INFO: 开始执行用例"adWords"
2020-04-10 16:09:16,384 - f:\GitRepo\auto_interface_test\basic\RunTestcase.py[line:82] - INFO: 数据：adWords执行成功
2020-04-10 16:09:16,433 - f:\GitRepo\auto_interface_test\basic\RunTestcase.py[line:34] - INFO: 开始执行用例"adWords123"
2020-04-10 16:09:16,554 - f:\GitRepo\auto_interface_test\basic\RunTestcase.py[line:86] - INFO: 数据：adWords123执行失败
2020-04-10 16:09:16,604 - f:\GitRepo\auto_interface_test\basic\RunTestcase.py[line:150] - INFO: 接口：测试接口4执行失败
2020-04-10 16:09:16,707 - f:\GitRepo\auto_interface_test\basic\RunTestcase.py[line:197] - INFO: 接口用例：'接口用例'执行完成
2020-04-10 16:16:08,199 - f:\GitRepo\auto_interface_test\basic\RunTestcase.py[line:116] - INFO: 接口用例：'接口用例'开始执行
2020-04-10 16:17:01,669 - f:\GitRepo\auto_interface_test\basic\RunTestcase.py[line:185] - INFO: 接口：测试接口1执行成功
2020-04-10 16:17:04,189 - f:\GitRepo\auto_interface_test\basic\RunTestcase.py[line:189] - INFO: 接口：测试接口2执行失败
2020-04-10 16:17:04,245 - f:\GitRepo\auto_interface_test\basic\RunTestcase.py[line:193] - INFO: 接口：测试接口3未执行
2020-04-10 16:17:04,546 - f:\GitRepo\auto_interface_test\basic\RunTestcase.py[line:137] - INFO: ***********调用数据驱动************
2020-04-10 16:17:04,547 - f:\GitRepo\auto_interface_test\basic\RunTestcase.py[line:34] - INFO: 开始执行用例""adWords":"""
2020-04-10 16:17:04,684 - f:\GitRepo\auto_interface_test\basic\RunTestcase.py[line:82] - INFO: 数据："adWords":""执行成功
2020-04-10 16:17:04,738 - f:\GitRepo\auto_interface_test\basic\RunTestcase.py[line:34] - INFO: 开始执行用例"adWords"
2020-04-10 16:17:04,887 - f:\GitRepo\auto_interface_test\basic\RunTestcase.py[line:82] - INFO: 数据：adWords执行成功
2020-04-10 16:17:04,989 - f:\GitRepo\auto_interface_test\basic\RunTestcase.py[line:34] - INFO: 开始执行用例"adWords"
2020-04-10 16:17:05,112 - f:\GitRepo\auto_interface_test\basic\RunTestcase.py[line:82] - INFO: 数据：adWords执行成功
2020-04-10 16:17:05,164 - f:\GitRepo\auto_interface_test\basic\RunTestcase.py[line:34] - INFO: 开始执行用例"adWords123"
2020-04-10 16:17:07,483 - f:\GitRepo\auto_interface_test\basic\RunTestcase.py[line:86] - INFO: 数据：adWords123执行失败
2020-04-10 16:17:07,537 - f:\GitRepo\auto_interface_test\basic\RunTestcase.py[line:150] - INFO: 接口：测试接口4执行失败
2020-04-10 16:17:07,652 - f:\GitRepo\auto_interface_test\basic\RunTestcase.py[line:197] - INFO: 接口用例：'接口用例'执行完成
2020-04-10 16:29:01,725 - f:\GitRepo\auto_interface_test\basic\RunTestcase.py[line:116] - INFO: 接口用例：'接口用例'开始执行
2020-04-10 16:29:01,927 - f:\GitRepo\auto_interface_test\basic\RunTestcase.py[line:189] - INFO: 接口：测试接口1执行失败
2020-04-10 16:29:02,116 - f:\GitRepo\auto_interface_test\basic\RunTestcase.py[line:189] - INFO: 接口：测试接口2执行失败
2020-04-10 16:29:02,168 - f:\GitRepo\auto_interface_test\basic\RunTestcase.py[line:193] - INFO: 接口：测试接口3未执行
2020-04-10 16:29:02,219 - f:\GitRepo\auto_interface_test\basic\RunTestcase.py[line:137] - INFO: ***********调用数据驱动************
2020-04-10 16:29:02,220 - f:\GitRepo\auto_interface_test\basic\RunTestcase.py[line:34] - INFO: 开始执行用例""adWords":"""
2020-04-10 16:29:02,352 - f:\GitRepo\auto_interface_test\basic\RunTestcase.py[line:86] - INFO: 数据："adWords":""执行失败
2020-04-10 16:29:02,409 - f:\GitRepo\auto_interface_test\basic\RunTestcase.py[line:34] - INFO: 开始执行用例"adWords"
2020-04-10 16:29:02,554 - f:\GitRepo\auto_interface_test\basic\RunTestcase.py[line:86] - INFO: 数据：adWords执行失败
2020-04-10 16:29:02,654 - f:\GitRepo\auto_interface_test\basic\RunTestcase.py[line:34] - INFO: 开始执行用例"adWords"
2020-04-10 16:29:02,795 - f:\GitRepo\auto_interface_test\basic\RunTestcase.py[line:86] - INFO: 数据：adWords执行失败
2020-04-10 16:29:02,848 - f:\GitRepo\auto_interface_test\basic\RunTestcase.py[line:34] - INFO: 开始执行用例"adWords123"
2020-04-10 16:29:02,965 - f:\GitRepo\auto_interface_test\basic\RunTestcase.py[line:86] - INFO: 数据：adWords123执行失败
2020-04-10 16:29:03,018 - f:\GitRepo\auto_interface_test\basic\RunTestcase.py[line:150] - INFO: 接口：测试接口4执行失败
2020-04-10 16:29:03,117 - f:\GitRepo\auto_interface_test\basic\RunTestcase.py[line:197] - INFO: 接口用例：'接口用例'执行完成
